<?xml version="1.0"?>

<robot name="b1_description" xmlns:xacro="http://www.ros.org/wiki/xacro">

    <xacro:include filename="$(find b1_description)/robots/const.xacro"/>
    <xacro:include filename="$(find b1_description)/robots/materials.xacro"/>
    <xacro:include filename="$(find b1_description)/robots/leg.xacro"/>
    <xacro:include filename="$(find b1_description)/robots/gazebo.xacro"/>

    <!-- Rotor related joint and link is only for demonstrate location. -->
    <!-- Actually, the rotor will rotate and the joint is not fixed. Reduction ratio should be considered. -->

    <!-- Debug mode will hung up the robot, use "true" or "false" to switch it. -->
    <xacro:if value="$(arg DEBUG)">
        <link name="world"/>
        <joint name="base_static_joint" type="fixed">
            <origin rpy="0 0 0" xyz="0 0 0"/>
            <parent link="world"/>
            <child link="base"/>
        </joint>
    </xacro:if> 

    <link name="base">
        <visual>
            <origin rpy="0 0 0" xyz="0 0 0"/>
            <geometry>
                <box size="0.001 0.001 0.001"/>
            </geometry>
        </visual>
    </link>

    <joint name="floating_base" type="fixed">
        <origin rpy="0 0 0" xyz="0 0 0"/>
        <parent link="base"/>
        <child link="trunk"/>
    </joint>

    <link name="trunk">
        <visual>
            <origin rpy="0 0 0" xyz="0 0 0"/>
            <geometry>
                <mesh filename="package://b1_description/meshes/visual/trunk.dae" scale="1 1 1"/>
            </geometry>
            <material name="orange"/>
        </visual>
        <collision>
            <origin rpy="0 0 0" xyz="0 0 0"/>
            <geometry>
                <box size="${trunk_length} ${trunk_width} ${trunk_height}"/>
            </geometry>
        </collision>
        <!-- <collision>
            <origin rpy="0 0 0" xyz="0 0 0"/>
            <geometry>
                <mesh filename="package://b1_description/meshes/visual/trunk.dae" scale="1 1 1"/>
            </geometry>
        </collision> -->
        <inertial>
            <origin rpy="0 0 0" xyz="${trunk_com_x} ${trunk_com_y} ${trunk_com_z}"/>
            <mass value="${trunk_mass}"/>
            <inertia
                ixx="${trunk_ixx}" ixy="${trunk_ixy}" ixz="${trunk_ixz}"
                iyy="${trunk_iyy}" iyz="${trunk_iyz}"
                izz="${trunk_izz}"/>  
        </inertial>
    </link>

    <joint name="imu_joint" type="fixed">
        <parent link="trunk"/>
        <child link="imu_link"/>
        <origin rpy="0 0 0" xyz="0 0 0"/>
    </joint>

    <link name="imu_link">
        <inertial>
            <mass value="0.001"/>
            <origin rpy="0 0 0" xyz="0 0 0"/>
            <inertia ixx="0.0001" ixy="0" ixz="0" iyy="0.0001" iyz="0" izz="0.0001"/>
        </inertial>
        <visual>
            <origin rpy="0 0 0" xyz="0 0 0"/>
            <geometry>
                <box size="0.001 0.001 0.001"/>
            </geometry>
            <material name="red"/>
        </visual>
        <collision>
            <origin rpy="0 0 0" xyz="0 0 0"/>
            <geometry>
                <box size=".001 .001 .001"/>
            </geometry>
        </collision>
    </link>

    <link name="b1_rslidar">
        <visual>
            <origin rpy="0 0 0" xyz="0 0 0"/>
            <geometry>
                <box size="0.2 0.2 0.2"/>
            </geometry>
        </visual>
    </link>

    <joint name="lidar_joint" type="fixed">
        <parent link="imu_link"/>
        <child link="b1_rslidar"/>
        <origin rpy="0 0 0" xyz="0.2 0 0.3"/>
    </joint>

    <link name="virtual_arm">
        <visual>
            <origin rpy="0 0 0" xyz="1.0 0.0 0.0"/>
            <geometry>
                <mesh filename="package://b1_description/meshes/visual/virtual_arm.dae"/>
            </geometry>
            <material name="red">
                <color rgba="1. 0. 0. 0.5"/>
            </material>
        </visual>
    </link>

    <joint name="virtual_arm_joint" type="revolute">
        <origin rpy="0 0 0" xyz="0 0 0"/>
        <parent link="trunk"/>
        <child link="virtual_arm"/>
        <axis xyz="0 0 1"/>
        <dynamics damping="0" friction="0"/>
        <limit effort="100.0" lower="-3.1416" upper="3.1416" velocity="20.0"/>
    </joint>

    <xacro:leg name="FR" mirror="-1" mirror_dae= "False" front_hind="1"  front_hind_dae="True"  />
    <xacro:leg name="FL" mirror="1"  mirror_dae="True"   front_hind="1"  front_hind_dae="True"  />
    <xacro:leg name="RR" mirror="-1" mirror_dae="False"  front_hind="-1" front_hind_dae="False" />
    <xacro:leg name="RL" mirror="1"  mirror_dae="True"   front_hind="-1" front_hind_dae="False" />

    <!-- <xacro:stairs stairs="15" xpos="0" ypos="2.0" zpos="0" /> -->

</robot>
